Workbook

Sheet Questions
A1: Question | B1: Le Tip ! | C1: Thème | D1: Sujet | F1: Remarques de Boubou
A2: Quelle est la première pensée que tu as au réveil la majorité des matins ? | C2: QUOTIDIEN | D2: Matin | E2: =COUNTIF(Questions!D:D,D2) -> 2
A3: Si tu pouvais changer une chose dans ta routine matinale actuelle, ce serait quoi ? | C3: QUOTIDIEN | D3: Matin | E3: =COUNTIF(Questions!D:D,D3) -> 2
A4: Quelle est la personne la plus intelligente du groupe ? | C4: ENTRE NOUS | D4: Meilleurs | E4: =COUNTIF(Questions!D:D,D4) -> 2
A5: Qui est la personne la plus drôle du groupe ? | C5: ENTRE NOUS | D5: Meilleurs | E5: =COUNTIF(Questions!D:D,D5) -> 2
A6: Y a-t-il un moment de ta vie dont tu n'as aucun souvenir mais qu'on t'a souvent raconté ? | C6: RETOUR EN ARRIERE | D6: Moments de vie | E6: =COUNTIF(Questions!D:D,D6) -> 2
A7: Quel moment de vie prenais-tu pour acquis et ne te satisfait pas, avant de te rendre compte qu'il était vraiment unique ? | C7: RETOUR EN ARRIERE | D7: Moments de vie | E7: =COUNTIF(Questions!D:D,D7) -> 2 | F7: 23
A8: Quelle qualité partages tu avec ton voisin de gauche ? | C8: ENTRE NOUS | D8: Partage | E8: =COUNTIF(Questions!D:D,D8) -> 2
A9: Si tu devais offrir un cadeau à ton voisin de gauche, que lui donnerais-tu ? | C9: ENTRE NOUS | D9: Partage | E9: =COUNTIF(Questions!D:D,D9) -> 2
A10: Quel est ton sens le plus développé ? | C10: QUOTIDIEN | D10: 5 sens | E10: =COUNTIF(Questions!D:D,D10) -> 2
A11: Si tu perdais un sens pour toujours, lequel choisis-tu de sacrifier ? | C11: QUOTIDIEN | D11: 5 sens | E11: =COUNTIF(Questions!D:D,D11) -> 2
A12: Quel est le mot qui résume toute ta période scolaire ? | C12: RETOUR EN ARRIERE | D12: A l'école | E12: =COUNTIF(Questions!D:D,D12) -> 2
A13: Quelle était ta matière préférée à l'école ? | C13: RETOUR EN ARRIERE | D13: A l'école | E13: =COUNTIF(Questions!D:D,D13) -> 2
A14: Si tu gagnais à la loterie, quel serait ton premier achat ? | C14: AMBITIONS | D14: Achats | E14: =COUNTIF(Questions!D:D,D14) -> 2
A15: Quelle est la chose la plus chère que tu possèdes en terme de prix ? | C15: AMBITIONS | D15: Achats | E15: =COUNTIF(Questions!D:D,D15) -> 2
A16: Quelle est l’activité manuelle que tu essayes d'apprendre actuellement ? | C16: PASSIONS & ACTIVITES | D16: Activité | E16: =COUNTIF(Questions!D:D,D16) -> 2
A17: Quelle est l'activité qui te détend totalement ? | C17: PASSIONS & ACTIVITES | D17: Activité | E17: =COUNTIF(Questions!D:D,D17) -> 2
A18: Quelle est la célébrité que tu trouves le plus BG ? | C18: CINE & MUSIQUE | D18: Admirateur | E18: =COUNTIF(Questions!D:D,D18) -> 2
A19: Si tu pouvais être n’importe quelle célébrité pendant une journée, qui serais-tu ? | C19: CINE & MUSIQUE | D19: Admirateur | E19: =COUNTIF(Questions!D:D,D19) -> 2
... A32: Quel est le film d’animation qui te rappelle ton enfance ? | C32: CINE & MUSIQUE | D32: Animation | E32: =COUNTIF(Questions!D:D,D32) -> 2
A33: Quel est le film d'animation le plus célèbre, que tu n'as-tu jamais vu ? | C33: CINE & MUSIQUE | D33: Animation | E33: =COUNTIF(Questions!D:D,D33) -> 2 | F33: 23
A34: Comment tu aimes fêter ton anniversaire ? | C34: QUOTIDIEN | D34: Anniversaire | E34: =COUNTIF(Questions!D:D,D34) -> 2
A35: Si tu pouvais choisir ton cadeau d'anniversaire parfait cette année, ce serait quoi ? | C35: QUOTIDIEN | D35: Anniversaire | E35: =COUNTIF(Questions!D:D,D35) -> 2
A36: Qui du groupe a l'air le plus sérieux mais est en réalité le plus fou ? | C36: ENTRE NOUS | D36: Apparences trompeuses | E36: =COUNTIF(Questions!D:D,D36) -> 2
A37: Qui du groupe a l'air le plus intelligent, mais est en vrai le plus con ? | C37: ENTRE NOUS | D37: Apparences trompeuses | E37: =COUNTIF(Questions!D:D,D37) -> 2
A38: Si tu pouvais concevoir ta maison idéale, comment elle serait ? | C38: PASSIONS & ACTIVITES | D38: Architecture | E38: =COUNTIF(Questions!D:D,D38) -> 2
A39: Quel est le bâtiment ou lieu que tu trouves le plus beau dans le monde ? | C39: PASSIONS & ACTIVITES | D39: Architecture | E39: =COUNTIF(Questions!D:D,D39) -> 2
A40: Si tu pouvais maîtriser parfaitement une forme d'art, laquelle choisirais-tu ? | C40: PASSIONS & ACTIVITES | D40: Art | E40: =COUNTIF(Questions!D:D,D40) -> 2
A41: Quelle œuvre d'art (tableau, sculpture, photo...) t'a un jour laissé sans voix ? | C41: PASSIONS & ACTIVITES | D41: Art | E41: =COUNTIF(Questions!D:D,D41) -> 2
A42: Quelle est la vision de toi-même dans 10 ans que tu portes mais n'avoues à presque personne ? | C42: AMBITIONS | D42: Aspirations profondes | E42: =COUNTIF(Questions!D:D,D42) -> 2
A43: Si l'argent et le regard des autres n'existaient pas, comment passerais-tu tes journées ? | C43: AMBITIONS | D43: Aspirations profondes | E43: =COUNTIF(Questions!D:D,D43) -> 2
A44: Quel est ton signe astrologique et est-ce que tu y crois ? Exemple de réponse : Scorpion/Oui | C44: QUI ES-TU ? | D44: Astrologie | E44: =COUNTIF(Questions!D:D,D44) -> 2
A45: Quelle est la superstitition à laquelle tu crois ? | C45: QUI ES-TU ? | D45: Astrologie | E45: =COUNTIF(Questions!D:D,D45) -> 2
... A50: Quel serait le titre de ton autobiographie ? | C50: RETOUR EN ARRIERE | D50: Autobiographie | E50: =COUNTIF(Questions!D:D,D50) -> 2
A51: C'est le moment d'écrire un livre sur la vie de quelqu'un, sur qui tu l'écris ? | C51: RETOUR EN ARRIERE | D51: Autobiographie | E51: =COUNTIF(Questions!D:D,D51) -> 2 | F51: 23
A52: Quel aspect ou défi de la vie future te fait le plus peur ? | C52: AMBITIONS | D52: Avenir | E52: =COUNTIF(Questions!D:D,D52) -> 2
A53: Quels sont les trois mots qui te viennent à l'esprit quand tu penses à l'avenir ? | C53: AMBITIONS | D53: Avenir | E53: =COUNTIF(Questions!D:D,D53) -> 2
A54: Quelle est la théorie du complot à laquelle tu adhères secrètement ? | C54: LES DOSSIERS | D54: Aveux | E54: =COUNTIF(Questions!D:D,D54) -> 2
A55: Quelle opinion impopulaire assumes-tu complètement ? | C55: LES DOSSIERS | D55: Aveux | E55: =COUNTIF(Questions!D:D,D55) -> 2
A56: Quel type d'humour te fait vraiment rire ? | C56: LES DOSSIERS | D56: Blague | E56: =COUNTIF(Questions!D:D,D56) -> 2
...

Sheet Nombre
A1: THEMES | B1: CATEGORIES | M1: Type de Question
A2: AMBITIONS | B2: DEEP | C2: =COUNTIF(Questions!C:C,Nombre!A2) -> 48 | E2: DEEP | F2: =COUNTIF(B:B,"DEEP") -> 4 | G2: =SUMIF(B:B,E2,C:C) -> 222 | M2: 5 sens | N2: =COUNTIF(Questions!D:D,Nombre!M2) -> 2 | Q2: Catégorie
A3: AMIS & FAMILLE | B3: FUN | C3: =COUNTIF(Questions!C:C,Nombre!A3) -> 40 | E3: FUN | F3: =COUNTIF(B:B,"FUN") -> 5 | G3: =SUMIF(B:B,E3,C:C) -> 168 | M3: A l'école | N3: =COUNTIF(Questions!D:D,Nombre!M86) -> 0 | Q3: Thème
A4: HOT | B4: FUN | C4: =COUNTIF(Questions!C:C,Nombre!A4) -> 16 | E4: ICEBREAKERS | F4: =COUNTIF(B:B,"ICEBREAKERS") -> 6 | G4: =SUMIF(B:B,E4,C:C) -> 282 | M4: A l'écolé | N4: =COUNTIF(Questions!D:D,Nombre!M85) -> 2 | Q4: Sujet
A5: CINE & MUSIQUE | B5: ICEBREAKERS | C5: =COUNTIF(Questions!C:C,Nombre!A5) -> 38 | M5: Achats | N5: =COUNTIF(Questions!D:D,Nombre!M3) -> 2
A6: ENTRE NOUS | B6: FUN | C6: =COUNTIF(Questions!C:C,Nombre!A6) -> 40 | M6: Activité | N6: =COUNTIF(Questions!D:D,Nombre!M4) -> 0
A7: FACE À TOI-MÊME | B7: DEEP | C7: =COUNTIF(Questions!C:C,Nombre!A7) -> 76 | H7: AMBITIONS | M7: Admirateur | N7: =COUNTIF(Questions!D:D,Nombre!M5) -> 2
A8: LES DOSSIERS | B8: FUN | C8: =COUNTIF(Questions!C:C,Nombre!A8) -> 52 | H8: AVENIR : | M8: Ambiance | N8: =COUNTIF(Questions!D:D,Nombre!M6) -> 2
A9: PASSIONS & ACTIVITES | B9: ICEBREAKERS | C9: =COUNTIF(Questions!C:C,Nombre!A9) -> 74 | M9: Amis perdus | N9: =COUNTIF(Questions!D:D,Nombre!M7) -> 2
A10: QUI ES-TU ? | B10: ICEBREAKERS | C10: =COUNTIF(Questions!C:C,Nombre!A10) -> 34 | M10: Amitié Durable | N10: =COUNTIF(Questions!D:D,Nombre!M8) -> 2
A11: QUOTIDIEN | B11: ICEBREAKERS | C11: =COUNTIF(Questions!C:C,Nombre!A11) -> 78 | M11: Amitié proche | N11: =COUNTIF(Questions!D:D,Nombre!M9) -> 2
A12: RETOUR EN ARRIERE | B12: DEEP | C12: =COUNTIF(Questions!C:C,Nombre!A12) -> 42 | M12: Amour propre | N12: =COUNTIF(Questions!D:D,Nombre!M10) -> 2
A13: VOYAGES & SORTIE | B13: ICEBREAKERS | C13: =COUNTIF(Questions!C:C,Nombre!A13) -> 38 | M13: Animal | N13: =COUNTIF(Questions!D:D,Nombre!M11) -> 2
A14: EMOTIONS & BIEN-ÊTRE | B14: DEEP | C14: =COUNTIF(Questions!C:C,Nombre!A14) -> 56 | M14: Animal de Compagnie | N14: =COUNTIF(Questions!D:D,Nombre!M12) -> 2
A15: MISE EN SITUATION | B15: ICEBREAKERS | C15: =COUNTIF(Questions!C:C,Nombre!A15) -> 20 | M15: Animation | N15: =COUNTIF(Questions!D:D,Nombre!M13) -> 2
A16: MES OPINIONS | B16: FUN | C16: =COUNTIF(Questions!C:C,Nombre!A16) -> 20 | M16: Anniversaire | N16: =COUNTIF(Questions!D:D,Nombre!M14) -> 2
C17: =COUNTIF(Questions!A2:A647,"") -> 0 | M17: Apparences trompeuses | N17: =COUNTIF(Questions!D:D,Nombre!M15) -> 2
C18: =SUM(C2:C17) -> 672 | M18: Architecture | N18: =COUNTIF(Questions!D:D,Nombre!M16) -> 2
M19: Art | N19: =COUNTIF(Questions!D:D,Nombre!M17) -> 2
M20: Aspirations profondes | N20: =COUNTIF(Questions!D:D,Nombre!M18) -> 2
M21: Astrologie | N21: =COUNTIF(Questions!D:D,Nombre!M19) -> 2
M22: Attentes | N22: =COUNTIF(Questions!D:D,Nombre!M20) -> 2
M23: Au dodo | N23: =COUNTIF(Questions!D:D,Nombre!M21) -> 2
M24: Au travail | N24: =COUNTIF(Questions!D:D,Nombre!M22) -> 2
M25: Autobiographie | N25: =COUNTIF(Questions!D:D,Nombre!M23) -> 2
M26: Avenir | N26: =COUNTIF(Questions!D:D,Nombre!M24) -> 2
M27: Aveux | N27: =COUNTIF(Questions!D:D,Nombre!M25) -> 2
M28: Blague | N28: =COUNTIF(Questions!D:D,Nombre!M27) -> 2
M29: Bodycount | N29: =COUNTIF(Questions!D:D,Nombre!M28) -> 2
M30: Boisson | N30: =COUNTIF(Questions!D:D,Nombre!M29) -> 2
M31: Bon délire | N31: =COUNTIF(Questions!D:D,Nombre!M30) -> 2
M32: Bruit | N32: =COUNTIF(Questions!D:D,Nombre!M31) -> 2
M33: Ca ME SOULE | N33: =COUNTIF(Questions!D:D,Nombre!M32) -> 2
M34: Cadeaux | N34: =COUNTIF(Questions!D:D,Nombre!M33) -> 0
M35: Cadeaux Reçus | N35: =COUNTIF(Questions!D:D,Nombre!M34) -> 2
M36: Célébrité | N36: =COUNTIF(Questions!D:D,Nombre!M35) -> 2
M37: Cette année | N37: =COUNTIF(Questions!D:D,Nombre!M36) -> 2
M38: Chance et malchance | N38: =COUNTIF(Questions!D:D,Nombre!M37) -> 2
M39: Changements | N39: =COUNTIF(Questions!D:D,Nombre!M38) -> 2
... M77: Destination | N77: =COUNTIF(Questions!D:D,Nombre!M76) -> 0
...

Sheet Noms Themes et Grilles
A1: AMBITIONS 🚀 Tes rêves, ton argent, ta vision ! Que veux-tu vraiment construire ?
A2: AMIS & FAMILLE🫂Des questions sur tes liens avec ceux qui comptent vraiment !
A3: HOT 🔞 En dehors des regards ! Pour les adultes uniquement
A4: CINÉ & MUSIQUE🎬Ce que tu écoutes, ce que tu regardes, ce que ça dit de toi sans que tu t'en rendes compte !
A5: ENTRE NOUS👀 Des questions sur la dynamique de groupe elle-même !
A6: FACE À TOI-MÊME🪞Pas de filtre : ce que tu sais de toi mais que tu dis rarement.
A7: LES DOSSIERS📂 Opinions tranchées, aveux gênants, Onskoné ou ou Onvastapé !
A8: PASSIONS & ACTIVITÉS🎯 Ce qui te fait vibrer dans la vie !
A9: QUI ES-TU ?🧬Ton introduction, et les premiers détails qui apprenent à savoir qui tu es !
A10: QUOTIDIEN☀️Le matin, les habitudes, les petits riens !
A11: RETOUR EN ARRIÈRE⏪L'enfance, les regrets, les tournants. Tout ce qui t'a construit !
A12: VOYAGES & SORTIE🌍 Ou tu vas et ou tu sors !
... A15: TES OPINIONS🗣️ Ce que tu penses à voix haute, sur plusieurs sujets particuliers !

Sheet 📊 Résumé
A1: Thème | B1: Nb Questions | C1: Nb Types
A2: AMBITIONS | B2: 44 | C2: 23
A3: AMIS & FAMILLE | B3: 30 | C3: 17
A4: AMOUR & SÉDUCTION | B4: 27 | C4: 14
A5: CINÉ & SÉRIES | B5: 27 | C5: 14
A6: ENTRE NOUS | B6: 33 | C6: 17
A7: FACE À TOI-MÊME | B7: 113 | C7: 57
A8: HUMOUR & DOSSIERS | B8: 47 | C8: 24
A9: LE MONDE | B9: 22 | C9: 11
A10: MUSIQUE | B10: 18 | C10: 10
A11: PASSIONS & CRÉA | B11: 98 | C11: 49
A12: QUI ES-TU ? | B12: 49 | C12: 26
A13: QUOTIDIEN | B13: 94 | C13: 49
... A17: TOTAL | B17: 705 | C17: 364
