Workbook

Sheet Questions
A1: Question | B1: Le Tip ! | C1: Thème | D1: Sujet | F1: Question Anglais | G1: Theme | H1: Sujet | J1: Remarques de Boubou
A2: Quelle est la première pensée que tu as au réveil la majorité des matins ? | C2: QUOTIDIEN | D2: Matin | E2: =COUNTIF(Questions!D:D,D2) -> 2 | F2: What's the first thought that goes through your mind when you wake up most mornings? | G2: DAILY LIFE | H2: Morning Routine | I2: =COUNTIF(Questions!H:H,H2) -> 2
A3: Si tu pouvais changer une chose dans ta routine matinale actuelle, ce serait quoi ? | C3: QUOTIDIEN | D3: Matin | E3: =COUNTIF(Questions!D:D,D3) -> 2 | F3: If you could change one thing about your current morning routine, what would it be? | G3: DAILY LIFE | H3: Morning Routine | I3: =COUNTIF(Questions!H:H,H3) -> 2
A4: Quelle est la personne la plus intelligente du groupe ? | C4: ENTRE NOUS | D4: Le meilleur | E4: =COUNTIF(Questions!D:D,D4) -> 2 | F4: Who's the most intelligent person in the group? | G4: BETWEEN US | H4: Best In Group | I4: =COUNTIF(Questions!H:H,H4) -> 2
A5: Qui est la personne la plus drôle du groupe ? | C5: ENTRE NOUS | D5: Le meilleur | E5: =COUNTIF(Questions!D:D,D5) -> 2 | F5: Who's the funniest person in the group? | G5: BETWEEN US | H5: Best In Group | I5: =COUNTIF(Questions!H:H,H5) -> 2
A6: Y a-t-il un moment de ta vie dont tu n'as aucun souvenir mais qu'on t'a souvent raconté ? | C6: RETOUR EN ARRIERE | D6: Moments de vie | E6: =COUNTIF(Questions!D:D,D6) -> 2 | F6: Is there a moment in your life you have no memory of, but that people have told you about many times? | G6: BACK IN THE DAY | H6: Life Moments | I6: =COUNTIF(Questions!H:H,H6) -> 2
A7: Quel moment de vie prenais-tu pour acquis et ne te satisfait pas, avant de te rendre compte qu'il était vraiment unique ? | C7: RETOUR EN ARRIERE | D7: Moments de vie | E7: =COUNTIF(Questions!D:D,D7) -> 2 | F7: What moment did you take for granted, only to later realize it was truly unique? | G7: BACK IN THE DAY | H7: Life Moments | I7: =COUNTIF(Questions!H:H,H7) -> 2 | J7: 23
A8: Quelle qualité partages tu avec ton voisin de gauche ? | C8: ENTRE NOUS | D8: Partage | E8: =COUNTIF(Questions!D:D,D8) -> 2 | F8: What quality do you share with the person on your left? | G8: BETWEEN US | H8: Sharing | I8: =COUNTIF(Questions!H:H,H8) -> 2
A9: Si tu devais offrir un cadeau à ton voisin de gauche, que lui donnerais-tu ? | C9: ENTRE NOUS | D9: Partage | E9: =COUNTIF(Questions!D:D,D9) -> 2 | F9: If you had to give a gift to the person on your left, what would you give them? | G9: BETWEEN US | H9: Sharing | I9: =COUNTIF(Questions!H:H,H9) -> 2
A10: Quel est ton sens le plus développé ? | C10: QUOTIDIEN | D10: 5 sens | E10: =COUNTIF(Questions!D:D,D10) -> 2 | F10: Which of your five senses is the most developed? | G10: DAILY LIFE | H10: The 5 Senses | I10: =COUNTIF(Questions!H:H,H10) -> 2
A11: Si tu perdais un sens pour toujours, lequel choisis-tu de sacrifier ? | C11: QUOTIDIEN | D11: 5 sens | E11: =COUNTIF(Questions!D:D,D11) -> 2 | F11: If you had to lose one sense forever, which one would you sacrifice? | G11: DAILY LIFE | H11: The 5 Senses | I11: =COUNTIF(Questions!H:H,H11) -> 2
A12: Quel est le mot qui résume toute ta période scolaire ? | C12: RETOUR EN ARRIERE | D12: A l'école | E12: =COUNTIF(Questions!D:D,D12) -> 2 | F12: What one word sums up your entire school life? | G12: BACK IN THE DAY | H12: School Days | I12: =COUNTIF(Questions!H:H,H12) -> 2
A13: Quelle était ta matière préférée à l'école ? | C13: RETOUR EN ARRIERE | D13: A l'école | E13: =COUNTIF(Questions!D:D,D13) -> 2 | F13: What was your favorite subject at school? | G13: BACK IN THE DAY | H13: School Days | I13: =COUNTIF(Questions!H:H,H13) -> 2
A14: Si tu gagnais à la loterie, quel serait ton premier achat ? | C14: AMBITIONS | D14: Achats | E14: =COUNTIF(Questions!D:D,D14) -> 2 | F14: If you won the lottery, what would be your first purchase? | G14: AMBITIONS | H14: Big Purchases | I14: =COUNTIF(Questions!H:H,H14) -> 2
A15: Quelle est la chose la plus chère que tu possèdes en terme de prix ? | C15: AMBITIONS | D15: Achats | E15: =COUNTIF(Questions!D:D,D15) -> 2 | F15: What's the most expensive thing you own? | G15: AMBITIONS | H15: Big Purchases | I15: =COUNTIF(Questions!H:H,H15) -> 2
A16: Quelle est l’activité manuelle que tu essayes d'apprendre actuellement ? | C16: PASSIONS & ACTIVITES | D16: Activité | E16: =COUNTIF(Questions!D:D,D16) -> 2 | F16: What manual skill are you currently trying to learn? | G16: HOBBIES & PASSIONS | H16: Activities | I16: =COUNTIF(Questions!H:H,H16) -> 2
A17: Quelle est l'activité qui te détend totalement ? | C17: PASSIONS & ACTIVITES | D17: Activité | E17: =COUNTIF(Questions!D:D,D17) -> 2 | F17: What activity completely relaxes you? | G17: HOBBIES & PASSIONS | H17: Activities | I17: =COUNTIF(Questions!H:H,H17) -> 2
A18: Quelle est la célébrité que tu trouves le plus BG ? | C18: CINE & MUSIQUE | D18: Admirateur | E18: =COUNTIF(Questions!D:D,D18) -> 2 | F18: Which celebrity do you find the most attractive? | G18: MOVIES & MUSIC | H18: Celebrity Crush | I18: =COUNTIF(Questions!H:H,H18) -> 2
A19: Si tu pouvais être n’importe quelle célébrité pendant une journée, qui serais-tu ? | C19: CINE & MUSIQUE | D19: Admirateur | E19: =COUNTIF(Questions!D:D,D19) -> 2 | F19: If you could be any celebrity for a day, who would you be? | G19: MOVIES & MUSIC | H19: Celebrity Crush | I19: =COUNTIF(Questions!H:H,H19) -> 2
... A32: Quel est le film d’animation qui te rappelle ton enfance ? | C32: CINE & MUSIQUE | D32: Animation | E32: =COUNTIF(Questions!D:D,D32) -> 2 | F32: Which animated film takes you back to your childhood? | G32: MOVIES & MUSIC | H32: Animated Films | I32: =COUNTIF(Questions!H:H,H32) -> 2
A33: Quel est le film d'animation le plus célèbre, que tu n'as-tu jamais vu ? | C33: CINE & MUSIQUE | D33: Animation | E33: =COUNTIF(Questions!D:D,D33) -> 2 | F33: What's the most famous animated film you've never actually seen? | G33: MOVIES & MUSIC | H33: Animated Films | I33: =COUNTIF(Questions!H:H,H33) -> 2 | J33: 23
A34: Comment tu aimes fêter ton anniversaire ? | C34: QUOTIDIEN | D34: Anniversaire | E34: =COUNTIF(Questions!D:D,D34) -> 2 | F34: How do you like to celebrate your birthday? | G34: DAILY LIFE | H34: Birthdays | I34: =COUNTIF(Questions!H:H,H34) -> 2
A35: Si tu pouvais choisir ton cadeau d'anniversaire parfait cette année, ce serait quoi ? | C35: QUOTIDIEN | D35: Anniversaire | E35: =COUNTIF(Questions!D:D,D35) -> 2 | F35: If you could choose your perfect birthday gift this year, what would it be? | G35: DAILY LIFE | H35: Birthdays | I35: =COUNTIF(Questions!H:H,H35) -> 2
A36: Qui du groupe a l'air le plus sérieux mais est en réalité le plus fou ? | C36: ENTRE NOUS | D36: Apparences trompeuses | E36: =COUNTIF(Questions!D:D,D36) -> 2 | F36: Who in the group seems the most serious but is actually the most wild? | G36: BETWEEN US | H36: Surprising Appearances | I36: =COUNTIF(Questions!H:H,H36) -> 2
A37: Qui du groupe a l'air le plus intelligent, mais est en vrai le plus con ? | C37: ENTRE NOUS | D37: Apparences trompeuses | E37: =COUNTIF(Questions!D:D,D37) -> 2 | F37: Who in the group seems the most intelligent but is actually the least? | G37: BETWEEN US | H37: Surprising Appearances | I37: =COUNTIF(Questions!H:H,H37) -> 2
A38: Si tu pouvais concevoir ta maison idéale, comment elle serait ? | C38: PASSIONS & ACTIVITES | D38: Architecture | E38: =COUNTIF(Questions!D:D,D38) -> 2 | F38: If you could design your dream home, what would it look like? | G38: HOBBIES & PASSIONS | H38: Architecture | I38: =COUNTIF(Questions!H:H,H38) -> 2
A39: Quel est le bâtiment ou lieu que tu trouves le plus beau dans le monde ? | C39: PASSIONS & ACTIVITES | D39: Architecture | E39: =COUNTIF(Questions!D:D,D39) -> 2 | F39: What building or place do you find the most beautiful in the world? | G39: HOBBIES & PASSIONS | H39: Architecture | I39: =COUNTIF(Questions!H:H,H39) -> 2
A40: Si tu pouvais maîtriser parfaitement une forme d'art, laquelle choisirais-tu ? | C40: PASSIONS & ACTIVITES | D40: Art | E40: =COUNTIF(Questions!D:D,D40) -> 2 | F40: If you could master any art form perfectly, which one would you choose? | G40: HOBBIES & PASSIONS | H40: Art | I40: =COUNTIF(Questions!H:H,H40) -> 2
A41: Quelle œuvre d'art (tableau, sculpture, photo...) t'a un jour laissé sans voix ? | C41: PASSIONS & ACTIVITES | D41: Art | E41: =COUNTIF(Questions!D:D,D41) -> 2 | F41: What work of art (painting, sculpture, photo...) once left you speechless? | G41: HOBBIES & PASSIONS | H41: Art | I41: =COUNTIF(Questions!H:H,H41) -> 2
A42: Quelle est la vision de toi-même dans 10 ans que tu portes mais n'avoues à presque personne ? | C42: AMBITIONS | D42: Aspirations profondes | E42: =COUNTIF(Questions!D:D,D42) -> 2 | F42: What vision of yourself in 10 years do you carry but almost never tell anyone? | G42: AMBITIONS | H42: Deep Aspirations | I42: =COUNTIF(Questions!H:H,H42) -> 2
A43: Si l'argent et le regard des autres n'existaient pas, comment passerais-tu tes journées ? | C43: AMBITIONS | D43: Aspirations profondes | E43: =COUNTIF(Questions!D:D,D43) -> 2 | F43: If money and other people's opinions didn't exist, how would you spend your days? | G43: AMBITIONS | H43: Deep Aspirations | I43: =COUNTIF(Questions!H:H,H43) -> 2
A44: Quel est ton signe astrologique et est-ce que tu y crois ? Exemple de réponse : Scorpion/Oui | C44: QUI ES-TU ? | D44: Astrologie | E44: =COUNTIF(Questions!D:D,D44) -> 2 | F44: What's your star sign and do you believe in it? Example answer: Scorpio/Yes | G44: ABOUT YOU | H44: Astrology | I44: =COUNTIF(Questions!H:H,H44) -> 2
A45: Quelle est la superstitition à laquelle tu crois ? | C45: QUI ES-TU ? | D45: Astrologie | E45: =COUNTIF(Questions!D:D,D45) -> 2 | F45: What superstition do you actually believe in? | G45: ABOUT YOU | H45: Astrology | I45: =COUNTIF(Questions!H:H,H45) -> 2
... A50: Quel serait le titre de ton autobiographie ? | C50: RETOUR EN ARRIERE | D50: Autobiographie | E50: =COUNTIF(Questions!D:D,D50) -> 2 | F50: What would the title of your autobiography be? | G50: BACK IN THE DAY | H50: Your Autobiography | I50: =COUNTIF(Questions!H:H,H50) -> 2
A51: C'est le moment d'écrire un livre sur la vie de quelqu'un, sur qui tu l'écris ? | C51: RETOUR EN ARRIERE | D51: Autobiographie | E51: =COUNTIF(Questions!D:D,D51) -> 2 | F51: If you had to write a book about someone's life, whose would it be? | G51: BACK IN THE DAY | H51: Your Autobiography | I51: =COUNTIF(Questions!H:H,H51) -> 2 | J51: 23
A52: Quel aspect ou défi de la vie future te fait le plus peur ? | C52: AMBITIONS | D52: Avenir | E52: =COUNTIF(Questions!D:D,D52) -> 2 | F52: What aspect or challenge of the future scares you the most? | G52: AMBITIONS | H52: The Future | I52: =COUNTIF(Questions!H:H,H52) -> 2
A53: Quels sont les trois mots qui te viennent à l'esprit quand tu penses à l'avenir ? | C53: AMBITIONS | D53: Avenir | E53: =COUNTIF(Questions!D:D,D53) -> 2 | F53: What three words come to mind when you think about the future? | G53: AMBITIONS | H53: The Future | I53: =COUNTIF(Questions!H:H,H53) -> 2
A54: Quelle est la théorie du complot à laquelle tu adhères secrètement ? | C54: LES DOSSIERS | D54: Aveux | E54: =COUNTIF(Questions!D:D,D54) -> 2 | F54: What conspiracy theory do you secretly believe in? | G54: THE RECEIPTS | H54: Confessions | I54: =COUNTIF(Questions!H:H,H54) -> 2
A55: Quelle opinion impopulaire assumes-tu complètement ? | C55: LES DOSSIERS | D55: Aveux | E55: =COUNTIF(Questions!D:D,D55) -> 2 | F55: What unpopular opinion do you fully stand by? | G55: THE RECEIPTS | H55: Confessions | I55: =COUNTIF(Questions!H:H,H55) -> 2
A56: Quel type d'humour te fait vraiment rire ? | C56: LES DOSSIERS | D56: Blague | E56: =COUNTIF(Questions!D:D,D56) -> 2 | F56: What type of humor actually makes you laugh? | G56: THE RECEIPTS | H56: Jokes | I56: =COUNTIF(Questions!H:H,H56) -> 2
...

Sheet Nombre
A1: THEMES | B1: CATEGORIES | M1: Type de Question
A2: AMBITIONS | B2: DEEP | C2: =COUNTIF(Questions!C:C,Nombre!A2) -> 48 | E2: DEEP | F2: =COUNTIF(B:B,"DEEP") -> 4 | G2: =SUMIF(B:B,E2,C:C) -> 220 | M2: 5 sens | N2: =COUNTIF(Questions!D:D,Nombre!M2) -> 2 | Q2: Catégorie
A3: AMIS & FAMILLE | B3: FUN | C3: =COUNTIF(Questions!C:C,Nombre!A3) -> 40 | E3: FUN | F3: =COUNTIF(B:B,"FUN") -> 5 | G3: =SUMIF(B:B,E3,C:C) -> 170 | M3: A l'école | N3: =COUNTIF(Questions!D:D,Nombre!M86) -> 0 | Q3: Thème
A4: HOT | B4: FUN | C4: =COUNTIF(Questions!C:C,Nombre!A4) -> 16 | E4: ICEBREAKERS | F4: =COUNTIF(B:B,"ICEBREAKERS") -> 6 | G4: =SUMIF(B:B,E4,C:C) -> 288 | M4: A l'écolé | N4: =COUNTIF(Questions!D:D,Nombre!M85) -> 2 | Q4: Sujet
A5: CINE & MUSIQUE | B5: ICEBREAKERS | C5: =COUNTIF(Questions!C:C,Nombre!A5) -> 38 | M5: Achats | N5: =COUNTIF(Questions!D:D,Nombre!M3) -> 2
A6: ENTRE NOUS | B6: FUN | C6: =COUNTIF(Questions!C:C,Nombre!A6) -> 40 | M6: Activité | N6: =COUNTIF(Questions!D:D,Nombre!M4) -> 0
A7: FACE À TOI-MÊME | B7: DEEP | C7: =COUNTIF(Questions!C:C,Nombre!A7) -> 76 | H7: AMBITIONS | M7: Admirateur | N7: =COUNTIF(Questions!D:D,Nombre!M5) -> 2
A8: LES DOSSIERS | B8: FUN | C8: =COUNTIF(Questions!C:C,Nombre!A8) -> 52 | H8: AVENIR : | M8: Ambiance | N8: =COUNTIF(Questions!D:D,Nombre!M6) -> 2
A9: PASSIONS & ACTIVITES | B9: ICEBREAKERS | C9: =COUNTIF(Questions!C:C,Nombre!A9) -> 76 | M9: Amis perdus | N9: =COUNTIF(Questions!D:D,Nombre!M7) -> 2
A10: QUI ES-TU ? | B10: ICEBREAKERS | C10: =COUNTIF(Questions!C:C,Nombre!A10) -> 34 | M10: Amitié Durable | N10: =COUNTIF(Questions!D:D,Nombre!M8) -> 2
A11: QUOTIDIEN | B11: ICEBREAKERS | C11: =COUNTIF(Questions!C:C,Nombre!A11) -> 80 | M11: Amitié proche | N11: =COUNTIF(Questions!D:D,Nombre!M9) -> 2
A12: RETOUR EN ARRIERE | B12: DEEP | C12: =COUNTIF(Questions!C:C,Nombre!A12) -> 40 | M12: Amour propre | N12: =COUNTIF(Questions!D:D,Nombre!M10) -> 2
A13: VOYAGES & SORTIE | B13: ICEBREAKERS | C13: =COUNTIF(Questions!C:C,Nombre!A13) -> 40 | M13: Animal | N13: =COUNTIF(Questions!D:D,Nombre!M11) -> 2
A14: EMOTIONS & BIEN-ÊTRE | B14: DEEP | C14: =COUNTIF(Questions!C:C,Nombre!A14) -> 56 | M14: Animal de Compagnie | N14: =COUNTIF(Questions!D:D,Nombre!M12) -> 2
A15: MISE EN SITUATION | B15: ICEBREAKERS | C15: =COUNTIF(Questions!C:C,Nombre!A15) -> 20 | M15: Animation | N15: =COUNTIF(Questions!D:D,Nombre!M13) -> 2
A16: MES OPINIONS | B16: FUN | C16: =COUNTIF(Questions!C:C,Nombre!A16) -> 22 | M16: Anniversaire | N16: =COUNTIF(Questions!D:D,Nombre!M14) -> 2
C17: =COUNTIF(Questions!A2:A647,"") -> 0 | M17: Apparences trompeuses | N17: =COUNTIF(Questions!D:D,Nombre!M15) -> 2
C18: =SUM(C2:C17) -> 678 | M18: Architecture | N18: =COUNTIF(Questions!D:D,Nombre!M16) -> 2
M19: Art | N19: =COUNTIF(Questions!D:D,Nombre!M17) -> 2
M20: Aspirations profondes | N20: =COUNTIF(Questions!D:D,Nombre!M18) -> 2
M21: Astrologie | N21: =COUNTIF(Questions!D:D,Nombre!M19) -> 2
M22: Attentes | N22: =COUNTIF(Questions!D:D,Nombre!M20) -> 2
M23: Au dodo | N23: =COUNTIF(Questions!D:D,Nombre!M21) -> 2
M24: Au travail | N24: =COUNTIF(Questions!D:D,Nombre!M22) -> 2
M25: Autobiographie | N25: =COUNTIF(Questions!D:D,Nombre!M23) -> 2
M26: Avenir | N26: =COUNTIF(Questions!D:D,Nombre!M24) -> 2
M27: Aveux | N27: =COUNTIF(Questions!D:D,Nombre!M25) -> 2
M28: Blague | N28: =COUNTIF(Questions!D:D,Nombre!M27) -> 2
M29: Bodycount | N29: =COUNTIF(Questions!D:D,Nombre!M28) -> 2
M30: Boisson | N30: =COUNTIF(Questions!D:D,Nombre!M29) -> 2
M31: Bon délire | N31: =COUNTIF(Questions!D:D,Nombre!M30) -> 2
M32: Bruit | N32: =COUNTIF(Questions!D:D,Nombre!M31) -> 2
M33: Ca ME SOULE | N33: =COUNTIF(Questions!D:D,Nombre!M32) -> 2
M34: Cadeaux | N34: =COUNTIF(Questions!D:D,Nombre!M33) -> 0
M35: Cadeaux Reçus | N35: =COUNTIF(Questions!D:D,Nombre!M34) -> 2
M36: Célébrité | N36: =COUNTIF(Questions!D:D,Nombre!M35) -> 2
M37: Cette année | N37: =COUNTIF(Questions!D:D,Nombre!M36) -> 2
M38: Chance et malchance | N38: =COUNTIF(Questions!D:D,Nombre!M37) -> 2
M39: Changements | N39: =COUNTIF(Questions!D:D,Nombre!M38) -> 2
... M77: Destination | N77: =COUNTIF(Questions!D:D,Nombre!M76) -> 0
...

Sheet Noms Themes
A1: AMBITIONS 🚀 | B1: AMBITIONS
A2: Tes rêves, ton argent, ta vision ! Que veux-tu vraiment construire ? | B2: Your dreams, your money, your vision. What are you actually building?
A3: →
A4: AMIS & FAMILLE 🫂 | B4: FAMILY & FRIENDS
A5: Des questions sur tes liens avec ceux qui comptent vraiment ! | B5: Questions about the people who matter most. No sugarcoating.
A6: →
A7: HOT 🔞 | B7: SPICYYY
A8: En dehors des regards ! Pour les adultes uniquement. | B8: Adults only. No audience, no filter, no limits.
A9: →
A10: CINÉ & MUSIQUE 🎬 | B10: MOVIES & MUSIC
A11: Ce que tu écoutes, ce que tu regardes, ce que ça dit de toi sans que tu t'en rendes compte ! | B11: What you watch, what you listen to, and what it says about you without you realizing it !
A12: →
A13: ENTRE NOUS 👀 | B13: BETWEEN US
A14: Des questions sur la dynamique de groupe elle-même ! | B14: Questions about the group itself. Let's get into it.
A15: →
A16: FACE À TOI-MÊME 🪞 | B16: IN THE MIRROR
A17: Pas de filtre : ce que tu sais de toi mais que tu dis rarement. | B17: No filter. The things you know about yourself but rarely say out loud.
A18: →
A19: LES DOSSIERS 📂 | B19: THE RECEIPTS
A20: Opinions tranchées, aveux gênants, Onskoné ou Onvastapé ! | B20: Sharp opinions, awkward confessions. We see you.
A21: →
A22: PASSIONS & ACTIVITÉS 🎯 | B22: HOBBIES & PASSIONS
A23: Ce qui te fait vibrer dans la vie ! | B23: The things that actually make you come alive.
A24: →
A25: QUI ES-TU ? 🧬 | B25: ABOUT YOU
A26: Ton introduction, et les premiers détails qui apprennent à savoir qui tu es ! | B26: Your intro. The first details that tell us who you really are.
A27: →
A28: QUOTIDIEN ☀️ | B28: DAILY LIFE
A29: Le matin, les habitudes, les petits riens ! | B29: Mornings, habits, routines. The small stuff that's actually everything.
A30: →
A31: RETOUR EN ARRIÈRE ⏪ | B31: BACK IN THE DAY
A32: L'enfance, les regrets, les tournants. Tout ce qui t'a construit ! | B32: Childhood, regrets, turning points. Everything that made you who you are.
A33: →
A34: VOYAGES & SORTIE 🌍 | B34: PARTIES & TRAVEL
A35: Où tu vas et où tu sors ! | B35: Where you travel, and what you get up to !
A36: →
A37: ÉMOTIONS & BIEN-ÊTRE 💛 | B37: FEELINGS
A38: Ce que tu ressens vraiment ! Petite introspection. | B38: What you're actually feeling. A little introspection goes a long way.
A39: →
A40: MISE EN SITUATION 🎭 | B40: WYD?
...

Sheet 📊 Résumé
A1: Thème | B1: Nb Questions | C1: Nb Types
A2: AMBITIONS | B2: 44 | C2: 23
A3: AMIS & FAMILLE | B3: 30 | C3: 17
A4: AMOUR & SÉDUCTION | B4: 27 | C4: 14
A5: CINÉ & SÉRIES | B5: 27 | C5: 14
A6: ENTRE NOUS | B6: 33 | C6: 17
A7: FACE À TOI-MÊME | B7: 113 | C7: 57
A8: HUMOUR & DOSSIERS | B8: 47 | C8: 24
A9: LE MONDE | B9: 22 | C9: 11
A10: MUSIQUE | B10: 18 | C10: 10
A11: PASSIONS & CRÉA | B11: 98 | C11: 49
A12: QUI ES-TU ? | B12: 49 | C12: 26
A13: QUOTIDIEN | B13: 94 | C13: 49
... A17: TOTAL | B17: 705 | C17: 364
